[2025-04-18T17:28:22.646+0000] {taskinstance.py:1159} INFO - Dependencies all met for dep_context=non-requeueable deps ti=<TaskInstance: data_ingestion.bq_transactions_salesdata_external_table_task manual__2025-04-18T03:20:57.015355+00:00 [queued]>
[2025-04-18T17:28:22.844+0000] {taskinstance.py:1159} INFO - Dependencies all met for dep_context=requeueable deps ti=<TaskInstance: data_ingestion.bq_transactions_salesdata_external_table_task manual__2025-04-18T03:20:57.015355+00:00 [queued]>
[2025-04-18T17:28:23.036+0000] {taskinstance.py:1361} INFO - Starting attempt 1 of 1
[2025-04-18T17:28:23.333+0000] {taskinstance.py:1382} INFO - Executing <Task(BigQueryCreateExternalTableOperator): bq_transactions_salesdata_external_table_task> on 2025-04-18 03:20:57.015355+00:00
[2025-04-18T17:28:23.411+0000] {standard_task_runner.py:57} INFO - Started process 1160 to run task
[2025-04-18T17:28:23.570+0000] {standard_task_runner.py:84} INFO - Running: ['***', 'tasks', 'run', 'data_ingestion', 'bq_transactions_salesdata_external_table_task', 'manual__2025-04-18T03:20:57.015355+00:00', '--job-id', '51', '--raw', '--subdir', 'DAGS_FOLDER/data_ingestion.py', '--cfg-path', '/tmp/tmpxbflc3wp']
[2025-04-18T17:28:23.715+0000] {standard_task_runner.py:85} INFO - Job 51: Subtask bq_transactions_salesdata_external_table_task
[2025-04-18T17:28:24.370+0000] {warnings.py:109} WARNING - /home/***/.local/lib/python3.10/site-packages/***/settings.py:195: DeprecationWarning: The sql_alchemy_conn option in [core] has been moved to the sql_alchemy_conn option in [database] - the old setting has been used, but please update your config.
  SQL_ALCHEMY_CONN = conf.get("database", "SQL_ALCHEMY_CONN")

[2025-04-18T17:28:25.013+0000] {task_command.py:416} INFO - Running <TaskInstance: data_ingestion.bq_transactions_salesdata_external_table_task manual__2025-04-18T03:20:57.015355+00:00 [running]> on host 30488d8db4a7
[2025-04-18T17:28:26.979+0000] {taskinstance.py:1662} INFO - Exporting env vars: AIRFLOW_CTX_DAG_OWNER='***' AIRFLOW_CTX_DAG_ID='data_ingestion' AIRFLOW_CTX_TASK_ID='bq_transactions_salesdata_external_table_task' AIRFLOW_CTX_EXECUTION_DATE='2025-04-18T03:20:57.015355+00:00' AIRFLOW_CTX_TRY_NUMBER='1' AIRFLOW_CTX_DAG_RUN_ID='manual__2025-04-18T03:20:57.015355+00:00'
[2025-04-18T17:28:26.984+0000] {crypto.py:82} WARNING - empty cryptography key - values will not be stored encrypted.
[2025-04-18T17:28:27.013+0000] {connection.py:232} WARNING - Connection schemes (type: google_cloud_platform) shall not contain '_' according to RFC3986.
[2025-04-18T17:28:27.050+0000] {base.py:73} INFO - Using connection ID 'google_cloud_default' for task execution.
[2025-04-18T17:28:29.655+0000] {taskinstance.py:1937} ERROR - Task failed with exception
Traceback (most recent call last):
  File "/home/airflow/.local/lib/python3.10/site-packages/airflow/providers/google/cloud/operators/bigquery.py", line 1777, in execute
    table = bq_hook.create_empty_table(
  File "/home/airflow/.local/lib/python3.10/site-packages/airflow/providers/google/common/hooks/base_google.py", line 475, in inner_wrapper
    return func(self, *args, **kwargs)
  File "/home/airflow/.local/lib/python3.10/site-packages/airflow/providers/google/cloud/hooks/bigquery.py", line 420, in create_empty_table
    return self.get_client(project_id=project_id, location=location).create_table(
  File "/home/airflow/.local/lib/python3.10/site-packages/google/cloud/bigquery/client.py", line 809, in create_table
    api_response = self._call_api(
  File "/home/airflow/.local/lib/python3.10/site-packages/google/cloud/bigquery/client.py", line 843, in _call_api
    return call()
  File "/home/airflow/.local/lib/python3.10/site-packages/google/api_core/retry/retry_unary.py", line 293, in retry_wrapped_func
    return retry_target(
  File "/home/airflow/.local/lib/python3.10/site-packages/google/api_core/retry/retry_unary.py", line 153, in retry_target
    _retry_error_helper(
  File "/home/airflow/.local/lib/python3.10/site-packages/google/api_core/retry/retry_base.py", line 212, in _retry_error_helper
    raise final_exc from source_exc
  File "/home/airflow/.local/lib/python3.10/site-packages/google/api_core/retry/retry_unary.py", line 144, in retry_target
    result = target()
  File "/home/airflow/.local/lib/python3.10/site-packages/google/cloud/_http/__init__.py", line 494, in api_request
    raise exceptions.from_http_response(response)
google.api_core.exceptions.BadRequest: 400 POST https://bigquery.googleapis.com/bigquery/v2/projects/fashion-retail-sales-project/datasets/fashion_sales_dataset/tables?prettyPrint=false: Field missing name
[2025-04-18T17:28:30.856+0000] {taskinstance.py:1400} INFO - Marking task as FAILED. dag_id=data_ingestion, task_id=bq_transactions_salesdata_external_table_task, execution_date=20250418T032057, start_date=20250418T172822, end_date=20250418T172830
[2025-04-18T17:28:31.298+0000] {standard_task_runner.py:104} ERROR - Failed to execute job 51 for task bq_transactions_salesdata_external_table_task (400 POST https://bigquery.googleapis.com/bigquery/v2/projects/fashion-retail-sales-project/datasets/fashion_sales_dataset/tables?prettyPrint=false: Field missing name; 1160)
[2025-04-18T17:28:32.048+0000] {local_task_job_runner.py:228} INFO - Task exited with return code 1
[2025-04-18T17:28:33.341+0000] {taskinstance.py:2778} INFO - 0 downstream tasks scheduled from follow-on schedule check
