[2025-04-18T15:12:44.010+0000] {taskinstance.py:1159} INFO - Dependencies all met for dep_context=non-requeueable deps ti=<TaskInstance: data_ingestion.local__data_to_gcs_task manual__2025-04-18T03:20:57.015355+00:00 [queued]>
[2025-04-18T15:12:44.084+0000] {taskinstance.py:1159} INFO - Dependencies all met for dep_context=requeueable deps ti=<TaskInstance: data_ingestion.local__data_to_gcs_task manual__2025-04-18T03:20:57.015355+00:00 [queued]>
[2025-04-18T15:12:44.086+0000] {taskinstance.py:1361} INFO - Starting attempt 1 of 1
[2025-04-18T15:12:44.129+0000] {taskinstance.py:1382} INFO - Executing <Task(PythonOperator): local__data_to_gcs_task> on 2025-04-18 03:20:57.015355+00:00
[2025-04-18T15:12:44.143+0000] {standard_task_runner.py:57} INFO - Started process 1023 to run task
[2025-04-18T15:12:44.191+0000] {standard_task_runner.py:84} INFO - Running: ['***', 'tasks', 'run', 'data_ingestion', 'local__data_to_gcs_task', 'manual__2025-04-18T03:20:57.015355+00:00', '--job-id', '41', '--raw', '--subdir', 'DAGS_FOLDER/data_ingestion.py', '--cfg-path', '/tmp/tmpi35fqqef']
[2025-04-18T15:12:44.241+0000] {standard_task_runner.py:85} INFO - Job 41: Subtask local__data_to_gcs_task
[2025-04-18T15:12:44.455+0000] {warnings.py:109} WARNING - /home/***/.local/lib/python3.10/site-packages/***/settings.py:195: DeprecationWarning: The sql_alchemy_conn option in [core] has been moved to the sql_alchemy_conn option in [database] - the old setting has been used, but please update your config.
  SQL_ALCHEMY_CONN = conf.get("database", "SQL_ALCHEMY_CONN")

[2025-04-18T15:12:44.606+0000] {task_command.py:416} INFO - Running <TaskInstance: data_ingestion.local__data_to_gcs_task manual__2025-04-18T03:20:57.015355+00:00 [running]> on host 65b150f242e5
[2025-04-18T15:12:45.195+0000] {taskinstance.py:1662} INFO - Exporting env vars: AIRFLOW_CTX_DAG_OWNER='***' AIRFLOW_CTX_DAG_ID='data_ingestion' AIRFLOW_CTX_TASK_ID='local__data_to_gcs_task' AIRFLOW_CTX_EXECUTION_DATE='2025-04-18T03:20:57.015355+00:00' AIRFLOW_CTX_TRY_NUMBER='1' AIRFLOW_CTX_DAG_RUN_ID='manual__2025-04-18T03:20:57.015355+00:00'
[2025-04-18T15:12:45.612+0000] {taskinstance.py:1937} ERROR - Task failed with exception
Traceback (most recent call last):
  File "/opt/airflow/dags/data_ingestion.py", line 47, in upload_data_to_gcs
    blob.upload_from_filename(file_path)
NameError: name 'file_path' is not defined

During handling of the above exception, another exception occurred:

Traceback (most recent call last):
  File "/home/airflow/.local/lib/python3.10/site-packages/airflow/operators/python.py", line 192, in execute
    return_value = self.execute_callable()
  File "/home/airflow/.local/lib/python3.10/site-packages/airflow/operators/python.py", line 209, in execute_callable
    return self.python_callable(*self.op_args, **self.op_kwargs)
  File "/opt/airflow/dags/data_ingestion.py", line 50, in upload_data_to_gcs
    logger.error(f'Failed to upload {file_path} to {destination_blob_name}: {e}')
NameError: name 'file_path' is not defined
[2025-04-18T15:12:45.666+0000] {taskinstance.py:1400} INFO - Marking task as FAILED. dag_id=data_ingestion, task_id=local__data_to_gcs_task, execution_date=20250418T032057, start_date=20250418T151244, end_date=20250418T151245
[2025-04-18T15:12:45.764+0000] {standard_task_runner.py:104} ERROR - Failed to execute job 41 for task local__data_to_gcs_task (name 'file_path' is not defined; 1023)
[2025-04-18T15:12:45.953+0000] {local_task_job_runner.py:228} INFO - Task exited with return code 1
[2025-04-18T15:12:46.012+0000] {taskinstance.py:2778} INFO - 0 downstream tasks scheduled from follow-on schedule check
