[2025-04-18T01:08:14.468+0000] {taskinstance.py:1159} INFO - Dependencies all met for dep_context=non-requeueable deps ti=<TaskInstance: data_ingestion.download_taxi_data manual__2025-04-18T01:07:59.833758+00:00 [queued]>
[2025-04-18T01:08:14.480+0000] {taskinstance.py:1159} INFO - Dependencies all met for dep_context=requeueable deps ti=<TaskInstance: data_ingestion.download_taxi_data manual__2025-04-18T01:07:59.833758+00:00 [queued]>
[2025-04-18T01:08:14.482+0000] {taskinstance.py:1361} INFO - Starting attempt 1 of 1
[2025-04-18T01:08:14.660+0000] {taskinstance.py:1382} INFO - Executing <Task(BashOperator): download_taxi_data> on 2025-04-18 01:07:59.833758+00:00
[2025-04-18T01:08:14.673+0000] {standard_task_runner.py:57} INFO - Started process 183 to run task
[2025-04-18T01:08:14.679+0000] {standard_task_runner.py:84} INFO - Running: ['***', 'tasks', 'run', 'data_ingestion', 'download_taxi_data', 'manual__2025-04-18T01:07:59.833758+00:00', '--job-id', '3', '--raw', '--subdir', 'DAGS_FOLDER/data_ingestion.py', '--cfg-path', '/tmp/tmp9evpsep8']
[2025-04-18T01:08:14.732+0000] {standard_task_runner.py:85} INFO - Job 3: Subtask download_taxi_data
[2025-04-18T01:08:14.774+0000] {warnings.py:109} WARNING - /home/***/.local/lib/python3.10/site-packages/***/settings.py:195: DeprecationWarning: The sql_alchemy_conn option in [core] has been moved to the sql_alchemy_conn option in [database] - the old setting has been used, but please update your config.
  SQL_ALCHEMY_CONN = conf.get("database", "SQL_ALCHEMY_CONN")

[2025-04-18T01:08:14.935+0000] {task_command.py:416} INFO - Running <TaskInstance: data_ingestion.download_taxi_data manual__2025-04-18T01:07:59.833758+00:00 [running]> on host 5b8bfd74a6a8
[2025-04-18T01:08:15.135+0000] {taskinstance.py:1662} INFO - Exporting env vars: AIRFLOW_CTX_DAG_OWNER='***' AIRFLOW_CTX_DAG_ID='data_ingestion' AIRFLOW_CTX_TASK_ID='download_taxi_data' AIRFLOW_CTX_EXECUTION_DATE='2025-04-18T01:07:59.833758+00:00' AIRFLOW_CTX_TRY_NUMBER='1' AIRFLOW_CTX_DAG_RUN_ID='manual__2025-04-18T01:07:59.833758+00:00'
[2025-04-18T01:08:15.139+0000] {subprocess.py:63} INFO - Tmp dir root location: /tmp
[2025-04-18T01:08:15.142+0000] {subprocess.py:75} INFO - Running command: ['/bin/bash', '-c', '/opt/***/scripts/download_data.sh ']
[2025-04-18T01:08:15.168+0000] {subprocess.py:86} INFO - Output:
[2025-04-18T01:08:15.292+0000] {subprocess.py:93} INFO - [2025-04-18 01:08:15] INFO: Script started, processing fashion retail stores dataset
[2025-04-18T01:08:15.341+0000] {subprocess.py:93} INFO - [2025-04-18 01:08:15] INFO: Downloading dataset from Kaggle...
[2025-04-18T01:09:32.831+0000] {subprocess.py:93} INFO - [2025-04-18 01:09:32] INFO: Extracting files to /opt/***/scripts/../data/raw...
[2025-04-18T01:09:32.834+0000] {subprocess.py:93} INFO - /opt/***/scripts/download_data.sh: line 40: unzip: command not found
[2025-04-18T01:09:32.899+0000] {subprocess.py:93} INFO - [2025-04-18 01:09:32] INFO: ERROR: Extraction failed. File may be corrupted
[2025-04-18T01:09:32.909+0000] {subprocess.py:97} INFO - Command exited with return code 1
[2025-04-18T01:09:32.974+0000] {taskinstance.py:1937} ERROR - Task failed with exception
Traceback (most recent call last):
  File "/home/airflow/.local/lib/python3.10/site-packages/airflow/operators/bash.py", line 210, in execute
    raise AirflowException(
airflow.exceptions.AirflowException: Bash command failed. The command returned a non-zero exit code 1.
[2025-04-18T01:09:32.987+0000] {taskinstance.py:1400} INFO - Marking task as FAILED. dag_id=data_ingestion, task_id=download_taxi_data, execution_date=20250418T010759, start_date=20250418T010814, end_date=20250418T010932
[2025-04-18T01:09:33.024+0000] {standard_task_runner.py:104} ERROR - Failed to execute job 3 for task download_taxi_data (Bash command failed. The command returned a non-zero exit code 1.; 183)
[2025-04-18T01:09:33.176+0000] {local_task_job_runner.py:228} INFO - Task exited with return code 1
[2025-04-18T01:09:33.242+0000] {taskinstance.py:2778} INFO - 0 downstream tasks scheduled from follow-on schedule check
