[2025-04-18T01:00:00.140+0000] {taskinstance.py:1159} INFO - Dependencies all met for dep_context=non-requeueable deps ti=<TaskInstance: data_ingestion.download_taxi_data manual__2025-04-18T00:56:44.885689+00:00 [queued]>
[2025-04-18T01:00:00.191+0000] {taskinstance.py:1159} INFO - Dependencies all met for dep_context=requeueable deps ti=<TaskInstance: data_ingestion.download_taxi_data manual__2025-04-18T00:56:44.885689+00:00 [queued]>
[2025-04-18T01:00:00.192+0000] {taskinstance.py:1361} INFO - Starting attempt 2 of 2
[2025-04-18T01:00:00.244+0000] {taskinstance.py:1382} INFO - Executing <Task(BashOperator): download_taxi_data> on 2025-04-18 00:56:44.885689+00:00
[2025-04-18T01:00:00.286+0000] {standard_task_runner.py:57} INFO - Started process 256 to run task
[2025-04-18T01:00:00.299+0000] {standard_task_runner.py:84} INFO - Running: ['***', 'tasks', 'run', 'data_ingestion', 'download_taxi_data', 'manual__2025-04-18T00:56:44.885689+00:00', '--job-id', '51', '--raw', '--subdir', 'DAGS_FOLDER/data_ingestion.py', '--cfg-path', '/tmp/tmp6vkuavr7']
[2025-04-18T01:00:00.341+0000] {standard_task_runner.py:85} INFO - Job 51: Subtask download_taxi_data
[2025-04-18T01:00:00.418+0000] {warnings.py:109} WARNING - /home/***/.local/lib/python3.10/site-packages/***/settings.py:195: DeprecationWarning: The sql_alchemy_conn option in [core] has been moved to the sql_alchemy_conn option in [database] - the old setting has been used, but please update your config.
  SQL_ALCHEMY_CONN = conf.get("database", "SQL_ALCHEMY_CONN")

[2025-04-18T01:00:00.693+0000] {task_command.py:416} INFO - Running <TaskInstance: data_ingestion.download_taxi_data manual__2025-04-18T00:56:44.885689+00:00 [running]> on host ada5a37ff2a8
[2025-04-18T01:00:01.232+0000] {taskinstance.py:1662} INFO - Exporting env vars: AIRFLOW_CTX_DAG_OWNER='***' AIRFLOW_CTX_DAG_ID='data_ingestion' AIRFLOW_CTX_TASK_ID='download_taxi_data' AIRFLOW_CTX_EXECUTION_DATE='2025-04-18T00:56:44.885689+00:00' AIRFLOW_CTX_TRY_NUMBER='2' AIRFLOW_CTX_DAG_RUN_ID='manual__2025-04-18T00:56:44.885689+00:00'
[2025-04-18T01:00:01.239+0000] {subprocess.py:63} INFO - Tmp dir root location: /tmp
[2025-04-18T01:00:01.246+0000] {subprocess.py:75} INFO - Running command: ['/bin/bash', '-c', '/opt/***/scripts/download_data.sh ']
[2025-04-18T01:00:01.445+0000] {subprocess.py:86} INFO - Output:
[2025-04-18T01:00:01.517+0000] {subprocess.py:93} INFO - [2025-04-18 01:00:01] INFO: Script started, processing fashion retail stores dataset
[2025-04-18T01:00:01.539+0000] {subprocess.py:93} INFO - mkdir: cannot create directory ‘/opt/***/scripts/../data/raw’: No such file or directory
[2025-04-18T01:00:01.546+0000] {subprocess.py:93} INFO - [2025-04-18 01:00:01] INFO: ERROR: Failed to create data directory /opt/***/scripts/../data/raw
[2025-04-18T01:00:01.548+0000] {subprocess.py:97} INFO - Command exited with return code 1
[2025-04-18T01:00:01.611+0000] {taskinstance.py:1937} ERROR - Task failed with exception
Traceback (most recent call last):
  File "/home/airflow/.local/lib/python3.10/site-packages/airflow/operators/bash.py", line 210, in execute
    raise AirflowException(
airflow.exceptions.AirflowException: Bash command failed. The command returned a non-zero exit code 1.
[2025-04-18T01:00:01.630+0000] {taskinstance.py:1400} INFO - Marking task as FAILED. dag_id=data_ingestion, task_id=download_taxi_data, execution_date=20250418T005644, start_date=20250418T010000, end_date=20250418T010001
[2025-04-18T01:00:01.723+0000] {standard_task_runner.py:104} ERROR - Failed to execute job 51 for task download_taxi_data (Bash command failed. The command returned a non-zero exit code 1.; 256)
[2025-04-18T01:00:01.827+0000] {local_task_job_runner.py:228} INFO - Task exited with return code 1
[2025-04-18T01:00:01.902+0000] {taskinstance.py:2778} INFO - 0 downstream tasks scheduled from follow-on schedule check
