[2025-04-18T00:57:04.649+0000] {taskinstance.py:1159} INFO - Dependencies all met for dep_context=non-requeueable deps ti=<TaskInstance: data_ingestion.download_taxi_data manual__2025-04-18T00:56:44.885689+00:00 [queued]>
[2025-04-18T00:57:04.857+0000] {taskinstance.py:1159} INFO - Dependencies all met for dep_context=requeueable deps ti=<TaskInstance: data_ingestion.download_taxi_data manual__2025-04-18T00:56:44.885689+00:00 [queued]>
[2025-04-18T00:57:04.858+0000] {taskinstance.py:1361} INFO - Starting attempt 1 of 1
[2025-04-18T00:57:05.128+0000] {taskinstance.py:1382} INFO - Executing <Task(BashOperator): download_taxi_data> on 2025-04-18 00:56:44.885689+00:00
[2025-04-18T00:57:05.146+0000] {standard_task_runner.py:57} INFO - Started process 163 to run task
[2025-04-18T00:57:05.161+0000] {standard_task_runner.py:84} INFO - Running: ['***', 'tasks', 'run', 'data_ingestion', 'download_taxi_data', 'manual__2025-04-18T00:56:44.885689+00:00', '--job-id', '50', '--raw', '--subdir', 'DAGS_FOLDER/data_ingestion.py', '--cfg-path', '/tmp/tmpi480029m']
[2025-04-18T00:57:05.357+0000] {standard_task_runner.py:85} INFO - Job 50: Subtask download_taxi_data
[2025-04-18T00:57:06.760+0000] {warnings.py:109} WARNING - /home/***/.local/lib/python3.10/site-packages/***/settings.py:195: DeprecationWarning: The sql_alchemy_conn option in [core] has been moved to the sql_alchemy_conn option in [database] - the old setting has been used, but please update your config.
  SQL_ALCHEMY_CONN = conf.get("database", "SQL_ALCHEMY_CONN")

[2025-04-18T00:57:07.311+0000] {task_command.py:416} INFO - Running <TaskInstance: data_ingestion.download_taxi_data manual__2025-04-18T00:56:44.885689+00:00 [running]> on host ada5a37ff2a8
[2025-04-18T00:57:07.697+0000] {taskinstance.py:1662} INFO - Exporting env vars: AIRFLOW_CTX_DAG_OWNER='***' AIRFLOW_CTX_DAG_ID='data_ingestion' AIRFLOW_CTX_TASK_ID='download_taxi_data' AIRFLOW_CTX_EXECUTION_DATE='2025-04-18T00:56:44.885689+00:00' AIRFLOW_CTX_TRY_NUMBER='1' AIRFLOW_CTX_DAG_RUN_ID='manual__2025-04-18T00:56:44.885689+00:00'
[2025-04-18T00:57:07.699+0000] {subprocess.py:63} INFO - Tmp dir root location: /tmp
[2025-04-18T00:57:07.701+0000] {subprocess.py:75} INFO - Running command: ['/bin/bash', '-c', '/opt/***/scripts/download_data.sh ']
[2025-04-18T00:57:07.744+0000] {subprocess.py:86} INFO - Output:
[2025-04-18T00:57:07.789+0000] {subprocess.py:93} INFO - [2025-04-18 00:57:07] INFO: Script started, processing fashion retail stores dataset
[2025-04-18T00:57:07.800+0000] {subprocess.py:93} INFO - mkdir: cannot create directory ‘/opt/***/scripts/../data/raw’: No such file or directory
[2025-04-18T00:57:07.808+0000] {subprocess.py:93} INFO - [2025-04-18 00:57:07] INFO: ERROR: Failed to create data directory /opt/***/scripts/../data/raw
[2025-04-18T00:57:07.809+0000] {subprocess.py:97} INFO - Command exited with return code 1
[2025-04-18T00:57:07.829+0000] {taskinstance.py:1937} ERROR - Task failed with exception
Traceback (most recent call last):
  File "/home/airflow/.local/lib/python3.10/site-packages/airflow/operators/bash.py", line 210, in execute
    raise AirflowException(
airflow.exceptions.AirflowException: Bash command failed. The command returned a non-zero exit code 1.
[2025-04-18T00:57:07.887+0000] {taskinstance.py:1400} INFO - Marking task as FAILED. dag_id=data_ingestion, task_id=download_taxi_data, execution_date=20250418T005644, start_date=20250418T005704, end_date=20250418T005707
[2025-04-18T00:57:07.912+0000] {standard_task_runner.py:104} ERROR - Failed to execute job 50 for task download_taxi_data (Bash command failed. The command returned a non-zero exit code 1.; 163)
[2025-04-18T00:57:08.067+0000] {local_task_job_runner.py:228} INFO - Task exited with return code 1
[2025-04-18T00:57:08.174+0000] {taskinstance.py:2778} INFO - 0 downstream tasks scheduled from follow-on schedule check
