[2025-04-18T17:46:40.330+0000] {taskinstance.py:1159} INFO - Dependencies all met for dep_context=non-requeueable deps ti=<TaskInstance: data_ingestion.bq_create_transactions_salesdata_partitioned_table_task manual__2025-04-18T03:20:57.015355+00:00 [queued]>
[2025-04-18T17:46:40.349+0000] {taskinstance.py:1159} INFO - Dependencies all met for dep_context=requeueable deps ti=<TaskInstance: data_ingestion.bq_create_transactions_salesdata_partitioned_table_task manual__2025-04-18T03:20:57.015355+00:00 [queued]>
[2025-04-18T17:46:40.351+0000] {taskinstance.py:1361} INFO - Starting attempt 1 of 1
[2025-04-18T17:46:40.413+0000] {taskinstance.py:1382} INFO - Executing <Task(BigQueryInsertJobOperator): bq_create_transactions_salesdata_partitioned_table_task> on 2025-04-18 03:20:57.015355+00:00
[2025-04-18T17:46:40.432+0000] {standard_task_runner.py:57} INFO - Started process 1615 to run task
[2025-04-18T17:46:40.445+0000] {standard_task_runner.py:84} INFO - Running: ['***', 'tasks', 'run', 'data_ingestion', 'bq_create_transactions_salesdata_partitioned_table_task', 'manual__2025-04-18T03:20:57.015355+00:00', '--job-id', '59', '--raw', '--subdir', 'DAGS_FOLDER/data_ingestion.py', '--cfg-path', '/tmp/tmpn_rtpi39']
[2025-04-18T17:46:40.453+0000] {standard_task_runner.py:85} INFO - Job 59: Subtask bq_create_transactions_salesdata_partitioned_table_task
[2025-04-18T17:46:40.519+0000] {warnings.py:109} WARNING - /home/***/.local/lib/python3.10/site-packages/***/settings.py:195: DeprecationWarning: The sql_alchemy_conn option in [core] has been moved to the sql_alchemy_conn option in [database] - the old setting has been used, but please update your config.
  SQL_ALCHEMY_CONN = conf.get("database", "SQL_ALCHEMY_CONN")

[2025-04-18T17:46:40.609+0000] {task_command.py:416} INFO - Running <TaskInstance: data_ingestion.bq_create_transactions_salesdata_partitioned_table_task manual__2025-04-18T03:20:57.015355+00:00 [running]> on host 30488d8db4a7
[2025-04-18T17:46:41.175+0000] {taskinstance.py:1662} INFO - Exporting env vars: AIRFLOW_CTX_DAG_OWNER='***' AIRFLOW_CTX_DAG_ID='data_ingestion' AIRFLOW_CTX_TASK_ID='bq_create_transactions_salesdata_partitioned_table_task' AIRFLOW_CTX_EXECUTION_DATE='2025-04-18T03:20:57.015355+00:00' AIRFLOW_CTX_TRY_NUMBER='1' AIRFLOW_CTX_DAG_RUN_ID='manual__2025-04-18T03:20:57.015355+00:00'
[2025-04-18T17:46:41.179+0000] {crypto.py:82} WARNING - empty cryptography key - values will not be stored encrypted.
[2025-04-18T17:46:41.180+0000] {connection.py:232} WARNING - Connection schemes (type: google_cloud_platform) shall not contain '_' according to RFC3986.
[2025-04-18T17:46:41.229+0000] {base.py:73} INFO - Using connection ID 'google_cloud_default' for task execution.
[2025-04-18T17:46:41.231+0000] {bigquery.py:2802} INFO - Executing: {'query': {'query': 'CREATE OR REPLACE TABLE fashion_sales_dataset.transactions_salesdata         PARTITION BY DATE(Date)         AS         SELECT * FROM fashion_sales_dataset.transactions_salesdata_external_table;', 'useLegacySql': False}}'
[2025-04-18T17:46:41.977+0000] {bigquery.py:1595} INFO - Inserting job ***_data_ingestion_bq_create_transactions_salesdata_partitioned_table_task_2025_04_18T03_20_57_015355_00_00_3ebd4dd150097e29c886ed9386f40b81
[2025-04-18T17:46:50.982+0000] {local_task_job_runner.py:294} WARNING - State of this instance has been externally set to restarting. Terminating instance.
[2025-04-18T17:46:51.000+0000] {process_utils.py:131} INFO - Sending 15 to group 1615. PIDs of all processes in the group: [1615]
[2025-04-18T17:46:51.007+0000] {process_utils.py:86} INFO - Sending the signal 15 to group 1615
[2025-04-18T17:46:51.009+0000] {taskinstance.py:1632} ERROR - Received SIGTERM. Terminating subprocesses.
[2025-04-18T17:46:51.460+0000] {bigquery.py:1486} INFO - Attempting to cancel job : fashion-retail-sales-project, ***_data_ingestion_bq_create_transactions_salesdata_partitioned_table_task_2025_04_18T03_20_57_015355_00_00_3ebd4dd150097e29c886ed9386f40b81
[2025-04-18T17:46:51.969+0000] {bigquery.py:1507} INFO - Waiting for canceled job fashion-retail-sales-project, ***_data_ingestion_bq_create_transactions_salesdata_partitioned_table_task_2025_04_18T03_20_57_015355_00_00_3ebd4dd150097e29c886ed9386f40b81 to finish.
[2025-04-18T17:46:57.190+0000] {bigquery.py:1507} INFO - Waiting for canceled job fashion-retail-sales-project, ***_data_ingestion_bq_create_transactions_salesdata_partitioned_table_task_2025_04_18T03_20_57_015355_00_00_3ebd4dd150097e29c886ed9386f40b81 to finish.
[2025-04-18T17:47:02.442+0000] {bigquery.py:1507} INFO - Waiting for canceled job fashion-retail-sales-project, ***_data_ingestion_bq_create_transactions_salesdata_partitioned_table_task_2025_04_18T03_20_57_015355_00_00_3ebd4dd150097e29c886ed9386f40b81 to finish.
[2025-04-18T17:47:07.603+0000] {bigquery.py:1498} INFO - Job successfully canceled: fashion-retail-sales-project, ***_data_ingestion_bq_create_transactions_salesdata_partitioned_table_task_2025_04_18T03_20_57_015355_00_00_3ebd4dd150097e29c886ed9386f40b81
[2025-04-18T17:47:07.623+0000] {taskinstance.py:1937} ERROR - Task failed with exception
Traceback (most recent call last):
  File "/home/airflow/.local/lib/python3.10/site-packages/airflow/providers/google/cloud/operators/bigquery.py", line 2858, in execute
    job.result(timeout=self.result_timeout, retry=self.result_retry)
  File "/home/airflow/.local/lib/python3.10/site-packages/google/cloud/bigquery/job/query.py", line 1681, in result
    while not is_job_done():
  File "/home/airflow/.local/lib/python3.10/site-packages/google/cloud/bigquery/job/query.py", line 1650, in is_job_done
    self._reload_query_results(retry=retry, **reload_query_results_kwargs)
  File "/home/airflow/.local/lib/python3.10/site-packages/google/cloud/bigquery/job/query.py", line 1448, in _reload_query_results
    self._query_results = self._client._get_query_results(
  File "/home/airflow/.local/lib/python3.10/site-packages/google/cloud/bigquery/client.py", line 2034, in _get_query_results
    resource = self._call_api(
  File "/home/airflow/.local/lib/python3.10/site-packages/google/cloud/bigquery/client.py", line 843, in _call_api
    return call()
  File "/home/airflow/.local/lib/python3.10/site-packages/google/api_core/retry/retry_unary.py", line 293, in retry_wrapped_func
    return retry_target(
  File "/home/airflow/.local/lib/python3.10/site-packages/google/api_core/retry/retry_unary.py", line 153, in retry_target
    _retry_error_helper(
  File "/home/airflow/.local/lib/python3.10/site-packages/google/api_core/retry/retry_base.py", line 212, in _retry_error_helper
    raise final_exc from source_exc
  File "/home/airflow/.local/lib/python3.10/site-packages/google/api_core/retry/retry_unary.py", line 144, in retry_target
    result = target()
  File "/home/airflow/.local/lib/python3.10/site-packages/google/cloud/_http/__init__.py", line 482, in api_request
    response = self._make_request(
  File "/home/airflow/.local/lib/python3.10/site-packages/google/cloud/_http/__init__.py", line 341, in _make_request
    return self._do_request(
  File "/home/airflow/.local/lib/python3.10/site-packages/google/cloud/_http/__init__.py", line 379, in _do_request
    return self.http.request(
  File "/home/airflow/.local/lib/python3.10/site-packages/google/auth/transport/requests.py", line 542, in request
    response = super(AuthorizedSession, self).request(
  File "/home/airflow/.local/lib/python3.10/site-packages/requests/sessions.py", line 589, in request
    resp = self.send(prep, **send_kwargs)
  File "/home/airflow/.local/lib/python3.10/site-packages/requests/sessions.py", line 703, in send
    r = adapter.send(request, **kwargs)
  File "/home/airflow/.local/lib/python3.10/site-packages/requests/adapters.py", line 486, in send
    resp = conn.urlopen(
  File "/home/airflow/.local/lib/python3.10/site-packages/urllib3/connectionpool.py", line 715, in urlopen
    httplib_response = self._make_request(
  File "/home/airflow/.local/lib/python3.10/site-packages/urllib3/connectionpool.py", line 467, in _make_request
    six.raise_from(e, None)
  File "<string>", line 3, in raise_from
  File "/home/airflow/.local/lib/python3.10/site-packages/urllib3/connectionpool.py", line 462, in _make_request
    httplib_response = conn.getresponse()
  File "/usr/local/lib/python3.10/http/client.py", line 1375, in getresponse
    response.begin()
  File "/usr/local/lib/python3.10/http/client.py", line 318, in begin
    version, status, reason = self._read_status()
  File "/usr/local/lib/python3.10/http/client.py", line 279, in _read_status
    line = str(self.fp.readline(_MAXLINE + 1), "iso-8859-1")
  File "/usr/local/lib/python3.10/socket.py", line 705, in readinto
    return self._sock.recv_into(b)
  File "/usr/local/lib/python3.10/ssl.py", line 1307, in recv_into
    return self.read(nbytes, buffer)
  File "/usr/local/lib/python3.10/ssl.py", line 1163, in read
    return self._sslobj.read(len, buffer)
  File "/home/airflow/.local/lib/python3.10/site-packages/airflow/models/taskinstance.py", line 1634, in signal_handler
    raise AirflowException("Task received SIGTERM signal")
airflow.exceptions.AirflowException: Task received SIGTERM signal
[2025-04-18T17:47:07.678+0000] {taskinstance.py:1400} INFO - Marking task as UP_FOR_RETRY. dag_id=data_ingestion, task_id=bq_create_transactions_salesdata_partitioned_table_task, execution_date=20250418T032057, start_date=20250418T174640, end_date=20250418T174707
[2025-04-18T17:47:07.699+0000] {standard_task_runner.py:104} ERROR - Failed to execute job 59 for task bq_create_transactions_salesdata_partitioned_table_task (Task received SIGTERM signal; 1615)
[2025-04-18T17:47:07.796+0000] {process_utils.py:79} INFO - Process psutil.Process(pid=1615, status='terminated', exitcode=1, started='17:46:39') (1615) terminated with exit code 1
